<sdf version='1.7'>
  <model name='exchanger'>
    <joint name='world_joint' type='fixed'>
      <pose relative_to='__model__'>0 0 0 0 -0 0</pose>
      <parent>world</parent>
      <child>exchanger</child>
    </joint>
    <link name='exchanger'>
      <pose relative_to='world_joint'>0 0 0 0 -0 0</pose>
      <inertial>
        <pose>0 0 0 0 -0 0</pose>
        <mass>1</mass>
        <inertia>
          <ixx>0.001</ixx>
          <ixy>0</ixy>
          <ixz>0</ixz>
          <iyy>0.001</iyy>
          <iyz>0</iyz>
          <izz>0.001</izz>
        </inertia>
      </inertial>
      <collision name='exchanger_collision'>
        <pose>0 0 0 0 -0 0</pose>
        <geometry>
          <mesh>
            <scale>1 1 1</scale>
            <uri>model://exchanger_des/meshes/exchanger.STL</uri>
          </mesh>
        </geometry>
      </collision>
      <visual name='exchanger_visual'>
        <pose>0 0 0 0 -0 0</pose>
        <geometry>
          <mesh>
            <scale>1 1 1</scale>
            <uri>model://exchanger_des/meshes/exchanger.STL</uri>
          </mesh>
        </geometry>
      </visual>
    </link>
    <joint name='J_px' type='prismatic'>
      <pose relative_to='exchanger'>0 0 0 0 -0 0</pose>
      <parent>exchanger</parent>
      <child>exchange_px</child>
      <axis>
        <xyz>1 0 0</xyz>
        <limit>
          <lower>-0.27</lower>
          <upper>0</upper>
          <effort>1000</effort>
          <velocity>1000</velocity>
        </limit>
        <dynamics>
          <spring_reference>0</spring_reference>
          <spring_stiffness>0</spring_stiffness>
        </dynamics>
      </axis>
    </joint>
    <link name='exchange_px'>
      <pose relative_to='J_px'>0 0 0 0 -0 0</pose>
      <inertial>
        <pose>0 -0 -0.01 0 -0 0</pose>
        <mass>0.09896</mass>
        <inertia>
          <ixx>4.3501e-05</ixx>
          <ixy>-3.7982e-21</ixy>
          <ixz>-1.5165e-22</ixz>
          <iyy>4.3501e-05</iyy>
          <iyz>-1.8521e-22</iyz>
          <izz>8.0405e-05</izz>
        </inertia>
      </inertial>
    </link>
    <joint name='J_py' type='prismatic'>
      <pose relative_to='exchange_px'>0 0 0 0 -0 0</pose>
      <parent>exchange_px</parent>
      <child>exchange_py</child>
      <axis>
        <xyz>0 1 0</xyz>
        <limit>
          <lower>-0.255</lower>
          <upper>0.255</upper>
          <effort>1000</effort>
          <velocity>1000</velocity>
        </limit>
        <dynamics>
          <spring_reference>0</spring_reference>
          <spring_stiffness>0</spring_stiffness>
        </dynamics>
      </axis>
    </joint>
    <link name='exchange_py'>
      <pose relative_to='J_py'>0 0 0 0 -0 0</pose>
      <inertial>
        <pose>0 -0 -0.01 0 -0 0</pose>
        <mass>0.09896</mass>
        <inertia>
          <ixx>4.3501e-05</ixx>
          <ixy>-3.7982e-21</ixy>
          <ixz>-1.5165e-22</ixz>
          <iyy>4.3501e-05</iyy>
          <iyz>-1.8521e-22</iyz>
          <izz>8.0405e-05</izz>
        </inertia>
      </inertial>
    </link>
    <joint name='J_pz' type='prismatic'>
      <pose relative_to='exchange_py'>0 0 0 0 -0 0</pose>
      <parent>exchange_py</parent>
      <child>exchange_pz</child>
      <axis>
        <xyz>0 0 1</xyz>
        <limit>
          <lower>0.72</lower>
          <upper>0.9</upper>
          <effort>1000</effort>
          <velocity>1000</velocity>
        </limit>
        <dynamics>
          <spring_reference>0</spring_reference>
          <spring_stiffness>0</spring_stiffness>
        </dynamics>
      </axis>
    </joint>
    <link name='exchange_pz'>
      <pose relative_to='J_pz'>0 0 0 0 -0 0</pose>
      <inertial>
        <pose>0 -0 -0.01 0 -0 0</pose>
        <mass>0.09896</mass>
        <inertia>
          <ixx>4.3501e-05</ixx>
          <ixy>-3.7982e-21</ixy>
          <ixz>-1.5165e-22</ixz>
          <iyy>4.3501e-05</iyy>
          <iyz>-1.8521e-22</iyz>
          <izz>8.0405e-05</izz>
        </inertia>
      </inertial>
    </link>
    <joint name='J_rz' type='revolute'>
      <pose relative_to='exchange_pz'>0 0 0 0 -0 0</pose>
      <parent>exchange_pz</parent>
      <child>exchange_rz</child>
      <axis>
        <xyz>0 0 1</xyz>
        <limit>
          <lower>-2.35619</lower>
          <upper>2.35619</upper>
          <effort>1000</effort>
          <velocity>1000</velocity>
        </limit>
        <dynamics>
          <spring_reference>0</spring_reference>
          <spring_stiffness>0</spring_stiffness>
        </dynamics>
      </axis>
    </joint>
    <link name='exchange_rz'>
      <pose relative_to='J_rz'>0 0 0 0 -0 0</pose>
      <inertial>
        <pose>0 -0 -0.01 0 -0 0</pose>
        <mass>0.09896</mass>
        <inertia>
          <ixx>4.3501e-05</ixx>
          <ixy>-3.7982e-21</ixy>
          <ixz>-1.5165e-22</ixz>
          <iyy>4.3501e-05</iyy>
          <iyz>-1.8521e-22</iyz>
          <izz>8.0405e-05</izz>
        </inertia>
      </inertial>
    </link>
    <joint name='J_ry' type='revolute'>
      <pose relative_to='exchange_rz'>0 0 0 0 -0 0</pose>
      <parent>exchange_rz</parent>
      <child>exchange_ry</child>
      <axis>
        <xyz>0 -1 0</xyz>
        <limit>
          <lower>0</lower>
          <upper>1.57079</upper>
          <effort>1000</effort>
          <velocity>1000</velocity>
        </limit>
        <dynamics>
          <spring_reference>0</spring_reference>
          <spring_stiffness>0</spring_stiffness>
        </dynamics>
      </axis>
    </joint>
    <link name='exchange_ry'>
      <pose relative_to='J_ry'>0 0 0 0 -0 0</pose>
      <inertial>
        <pose>0 -0 -0.01 0 -0 0</pose>
        <mass>0.09896</mass>
        <inertia>
          <ixx>4.3501e-05</ixx>
          <ixy>-3.7982e-21</ixy>
          <ixz>-1.5165e-22</ixz>
          <iyy>4.3501e-05</iyy>
          <iyz>-1.8521e-22</iyz>
          <izz>8.0405e-05</izz>
        </inertia>
      </inertial>
    </link>
    <joint name='J_rx' type='revolute'>
      <pose relative_to='exchange_ry'>0 0 0 0 -0 0</pose>
      <parent>exchange_ry</parent>
      <child>entry</child>
      <axis>
        <xyz>1 0 0</xyz>
        <limit>
          <lower>-0.78539</lower>
          <upper>0.78539</upper>
          <effort>1000</effort>
          <velocity>1000</velocity>
        </limit>
        <dynamics>
          <spring_reference>0</spring_reference>
          <spring_stiffness>0</spring_stiffness>
        </dynamics>
      </axis>
    </joint>
    <link name='entry'>
      <pose relative_to='J_rx'>0 0 0 0 -0 0</pose>
      <inertial>
        <pose>-0.07275 -0.033 0.03425 0 -0 0</pose>
        <mass>2</mass>
        <inertia>
          <ixx>0.0382734</ixx>
          <ixy>0.00516525</ixy>
          <ixz>-0.00498337</ixz>
          <iyy>0.0216235</iyy>
          <iyz>0.007124</iyz>
          <izz>0.0418201</izz>
        </inertia>
      </inertial>
      <collision name='entry_collision'>
        <pose>0 0 0 0 -0 0</pose>
        <geometry>
          <mesh>
            <scale>1 1 1</scale>
            <uri>model://exchanger_des/meshes/entry.STL</uri>
          </mesh>
        </geometry>
      </collision>
      <visual name='entry_visual'>
        <pose>0 0 0 0 -0 0</pose>
        <geometry>
          <mesh>
            <scale>1 1 1</scale>
            <uri>model://exchanger_des/meshes/entry.STL</uri>
          </mesh>
        </geometry>
      </visual>
      <visual name='entry_fixed_joint_lump__front_lightbar1_visual_1'>
        <pose>0 -0.137 0.137 3.14 1.5708 0</pose>
        <geometry>
          <mesh>
            <scale>1 1 1</scale>
            <uri>model://exchanger_des/meshes/front_light.STL</uri>
          </mesh>
        </geometry>
      </visual>
      <visual name='entry_fixed_joint_lump__left_lightbar_visual_2'>
        <pose>-0.1455 0.144 0 1.57 -0 0</pose>
        <geometry>
          <mesh>
            <scale>1 1 1</scale>
            <uri>model://exchanger_des/meshes/side_light.STL</uri>
          </mesh>
        </geometry>
      </visual>
      <visual name='entry_fixed_joint_lump__right_lightbar_visual_3'>
        <pose>-0.1455 -0.139 0 1.57 -0 0</pose>
        <geometry>
          <mesh>
            <scale>1 1 1</scale>
            <uri>model://exchanger_des/meshes/side_light.STL</uri>
          </mesh>
        </geometry>
      </visual>
    </link>
  </model>
</sdf>
